 16:43 8/4/2017 ef
 16:43 8/4/2017 ef
 16:45 8/4/2017 ef
 16:45 8/4/2017 ef
 16:45 8/4/2017 ef
 16:45 8/4/2017 ef
 16:45 8/4/2017 ef
 16:45 8/4/2017 ef
 16:45 8/4/2017 ef
 16:45 8/4/2017 ef
 16:45 8/4/2017 ef
 16:46 8/4/2017 saad
 16:46 8/4/2017 saad
 16:46 8/4/2017 saad
 16:47 8/4/2017 saad
 16:47 8/4/2017 saad
 16:47 8/4/2017 saad
 16:47 8/4/2017 saad
 16:47 8/4/2017 saad
 16:47 8/4/2017 saad
 16:47 8/4/2017 saad
 16:47 8/4/2017 saad
 16:47 8/4/2017 saad
 16:47 8/4/2017 saad
 16:48 8/4/2017 saad
 16:48 8/4/2017 saad
 16:48 8/4/2017 saad
 16:48 8/4/2017 saad
 16:48 8/4/2017 saad
 16:48 8/4/2017 saad
 16:48 8/4/2017 saad
 16:48 8/4/2017 saad
Internal Server Error: /ex02/
Traceback (most recent call last):
  File "/Users/aollivie/python/d04/ex02/django_venv/lib/python3.4/site-packages/django/core/handlers/exception.py", line 41, in inner
    response = get_response(request)
  File "/Users/aollivie/python/d04/ex02/django_venv/lib/python3.4/site-packages/django/core/handlers/base.py", line 187, in _get_response
    response = self.process_exception_by_middleware(e, request)
  File "/Users/aollivie/python/d04/ex02/django_venv/lib/python3.4/site-packages/django/core/handlers/base.py", line 185, in _get_response
    response = wrapped_callback(request, *callback_args, **callback_kwargs)
  File "/Users/aollivie/python/d04/ex02/d04/ex02/views.py", line 33, in ex02
    return render(request, 'ex02/form.html', {'form':form,'list_logs': content, 'callback':t })
NameError: name 't' is not defined
 16:48 8/4/2017 saad
 16:48 8/4/2017 saad
 16:48 8/4/2017 saad
 16:49 8/4/2017 saad
 16:49 8/4/2017 saad
 16:49 8/4/2017 saad
 16:49 8/4/2017 saad
 16:49 8/4/2017 saad
 16:49 8/4/2017 saad
 16:49 8/4/2017 saad
 16:49 8/4/2017 saad
 16:49 8/4/2017 saad
